Workbook

Sheet mol% to wt% Conversions
A1: MOLE FRACTION (mol%) TO MASS FRACTION (wt%) CONVERSION
A2: Source: Companies Data Questionnaire - MIDOR.XLSX (January 2025)
A4: DATABASE
A5: Component | B5: Formula | C5: MW (g/mol) | D5: Reference
A6: Hydrogen | B6: H₂ | C6: 2.016 | D6: Perry's Handbook (9th Ed)
A7: Methane | B7: CH₄ | C7: 16.042 | D7: Perry's Handbook (9th Ed)
A8: Ethane | B8: C₂H₆ | C8: 30.069 | D8: Perry's Handbook (9th Ed)
A9: Ethylene | B9: C₂H₄ | C9: 28.053 | D9: Perry's Handbook (9th Ed)
A10: Propane | B10: C₃H₈ | C10: 44.096 | D10: Perry's Handbook (9th Ed)
A11: Propylene | B11: C₃H₆ | C11: 42.08 | D11: Perry's Handbook (9th Ed)
A12: Butane | B12: n-C₄H₁₀ | C12: 58.122 | D12: Perry's Handbook (9th Ed)
A13: Isobutane | B13: i-C₄H₁₀ | C13: 58.123 | D13: Perry's Handbook (9th Ed)
A14: Butylene | B14: C4H8 | C14: 56.106 | D14: Perry's Handbook (9th Ed)
A15: C5+ | B15: C₅-C₇ | C15: 85
A16: Pentane | B16: C5-H10 | C16: 72.149 | D16: Perry's Handbook (9th Ed)
A17: IsoPentane | B17: i-C5H10 | C17: 72.15 | D17: Perry's Handbook (9th Ed)
A18: Hexane | B18: C6H12 | C18: 86.16 | D18: Perry's Handbook (9th Ed)
A19: H2S | B19: H2S | C19: 34.08 | D19: Perry's Handbook (9th Ed)
A20: Carbon Monoxide | B20: CO | C20: 28.01 | D20: Perry's Handbook (9th Ed)
A21: Carbon Dioxide | B21: CO₂ | C21: 44.01 | D21: Perry's Handbook (9th Ed)
A22: Nitrogen | B22: N₂ | C22: 28.014 | D22: Perry's Handbook (9th Ed)
A25: CONVERSION METHODOLOGY
A26: Step 1: Calculate mass contribution = mol% × MW
A27: Step 2: Calculate wt% = (mass contribution / total mass) × 100
A29: STREAM: FLARE GAS (Old )
A30: Source: MIDOR.XLSX → 'Flared Gases' sheet → average 2025 data
A31: Component | B31: mol% | C31: MW (g/mol) | D31: Mol fraction | E31: Mass Contrib | F31: wt fraction | G31: Wt %
A32: Hydrogen | B32: 66.823331 | C32: =$C$6 -> 2.016 | D32: =B32/100 -> 0.66823331 | E32: =D32*C32 -> 1.3471584 | F32: =E32/$E$46 -> 0.1222633 | G32: =F32*100 -> 12.22633
A33: Methane | B33: 18.035802 | C33: =$C$7 -> 16.042 | D33: =B33/100 -> 0.18035802 | E33: =D33*C33 -> 2.8933034 | F33: =E33/$E$46 -> 0.26258591 | G33: =F33*100 -> 26.258591
A34: Ethane | B34: 3.9262561 | C34: =$C$8 -> 30.069 | D34: =B34/100 -> 0.039262561 | E34: =D34*C34 -> 1.180586 | F34: =E34/$E$46 -> 0.10714578 | G34: =F34*100 -> 10.714578
A35: Ethylene | B35: 0.12777778 | C35: =$C$9 -> 28.053 | D35: =B35/100 -> 0.0012777778 | E35: =D35*C35 -> 0.0358455 | F35: =E35/$E$46 -> 0.00325321 | G35: =F35*100 -> 0.325321
A36: Propane | B36: 3.1095404 | C36: =$C$10 -> 44.096 | D36: =B36/100 -> 0.031095404 | E36: =D36*C36 -> 1.371183 | F36: =E36/$E$46 -> 0.12444368 | G36: =F36*100 -> 12.444368
A37: Propylene | B37: 0.22731021 | C37: =$C$11 -> 42.08 | D37: =B37/100 -> 0.0022731021 | E37: =D37*C37 -> 0.095652135 | F37: =E37/$E$46 -> 0.0086810472 | G37: =F37*100 -> 0.86810472
A38: Butane | B38: 1.7354239 | C38: =$C$12 -> 58.122 | D38: =B38/100 -> 0.017354239 | E38: =D38*C38 -> 1.0086631 | F38: =E38/$E$46 -> 0.091542672 | G38: =F38*100 -> 9.1542672
A39: Butylene | B39: 1.558775 | C39: =$C$14 -> 56.106 | D39: =B39/100 -> 0.01558775 | E39: =D39*C39 -> 0.87456632 | F39: =E39/$E$46 -> 0.079372525 | G39: =F39*100 -> 7.9372525
A40: Pentane | B40: 0.58131229 | C40: =$C$16 -> 72.149 | D40: =B40/100 -> 0.0058131229 | E40: =D40*C40 -> 0.41941101 | F40: =E40/$E$46 -> 0.03806425 | G40: =F40*100 -> 3.806425
A41: Hexane | B41: 0.49837803 | C41: =$C$18 -> 86.16 | D41: =B41/100 -> 0.0049837803 | E41: =D41*C41 -> 0.42940251 | F41: =E41/$E$46 -> 0.038971043 | G41: =F41*100 -> 3.8971043
A42: H2S | B42: 0.00043499577 | C42: =$C$19 -> 34.08 | D42: =B42/100 -> 4.3499577e-06 | E42: =D42*C42 -> 0.00014824656 | F42: =E42/$E$46 -> 1.345433e-05 | G42: =F42*100 -> 0.001345433
A43: Carbon Monoxide | B43: 0.88356481 | C43: =$C$20 -> 28.01 | D43: =B43/100 -> 0.0088356481 | E43: =D43*C43 -> 0.2474865 | F43: =E43/$E$46 -> 0.022460994 | G43: =F43*100 -> 2.2460994
A44: Carbon Dioxide | B44: 1.1412997 | C44: =$C$21 -> 44.01 | D44: =B44/100 -> 0.011412997 | E44: =D44*C44 -> 0.50228601 | F44: =E44/$E$46 -> 0.04558569 | G44: =F44*100 -> 4.558569
...

Sheet Heat Content Calculations
A1: LOWER HEATING VALUE (LHV) CALCULATIONS
A2: Source: Component mol% from 'mol% to wt% Conversions' sheet | LHV values from GPSA Engineering Data Book
A4: UNIT CONVERSION FACTORS
A5: Conversion | B5: Factor | C5: Formula | D5: Reference
A6: 1 scf → Nm³ | B6: 0.02832 | C6: 1 scf = 0.02832 Nm³ | D6: Standard (60°F, 1atm → 0°C, 1atm)
A7: 1 BTU → kcal | B7: 0.252 | C7: 1 BTU = 0.252 kcal | D7: Thermodynamic
A8: 1 BTU → kJ | B8: 1.055 | C8: 1 BTU = 1.055 kJ | D8: Thermodynamic
A9: 1 BTU → MJ | B9: 0.001055 | C9: 1 BTU = 0.001055 MJ | D9: Thermodynamic
A10: 1 lb → kg | B10: 0.4536 | C10: 1 lb = 0.4536 kg | D10: Mass conversion
A11: BTU/scf → BTU/Nm³ | B11: 35.3147 | C11: =1/0.02832 -> 35.310734 | D11: Volume basis
A12: BTU/scf → kcal/Nm³ | B12: 8.8993 | C12: =0.252 * 35.3147 -> 8.8993044 | D12: Combined
A13: BTU/scf → MJ/Nm³ | B13: 0.03727 | C13: =0.001055 * 35.3147 -> 0.037257009 | D13: Combined
A14: BTU/lb → kcal/kg | B14: 0.5556 | C14: =0.252 / 0.4536 -> 0.55555556 | D14: Mass basis
A15: BTU/lb → MJ/kg | B15: 0.002326 | C15: =0.001055 / 0.4536 -> 0.0023258377 | D15: Mass basis
A17: LHV DATABASE (NET HEATING VALUE)
A18: Component | B18: Formula | C18: MW (g/mol) | D18: LHV (BTU/scf) | E18: LHV (BTU/lb) | F18: Reference
A19: Hydrogen | B19: H₂ | C19: 2.016 | D19: 275 | E19: 51623 | F19: GPSA
A20: Methane | B20: CH₄ | C20: 16.042 | D20: 911 | E20: 21502 | F20: GPSA
A21: Ethane | B21: C₂H₆ | C21: 30.069 | D21: 1622 | E21: 20416 | F21: GPSA
A22: Ethylene | B22: C₂H₄ | C22: 28.053 | D22: 1513 | E22: 20409 | F22: GPSA
A23: Propane | B23: C₃H₈ | C23: 44.096 | D23: 2316 | E23: 19879 | F23: GPSA
A24: Propylene | B24: C₃H₆ | C24: 42.08 | D24: 2185 | E24: 19646 | F24: GPSA
A25: n-Butane | B25: n-C₄H₁₀ | C25: 58.122 | D25: 3012 | E25: 19614 | F25: GPSA
A26: Isobutane | B26: i-C₄H₁₀ | C26: 58.123 | D26: 2999 | E26: 19519 | F26: GPSA
A27: Butylene | B27: C₄H₈ | C27: 56.106 | D27: 2885 | E27: 19466 | F27: GPSA
A28: n-Pentane | B28: n-C₅H₁₂ | C28: 72.149 | D28: 3707 | E28: 19448 | F28: GPSA
A29: Isopentane | B29: i-C₅H₁₂ | C29: 72.15 | D29: 3698 | E29: 19395 | F29: GPSA
A30: n-Hexane | B30: C₆H₁₄ | C30: 86.16 | D30: 4404 | E30: 19346 | F30: GPSA
... A35: Nitrogen | B35: N₂ | C35: 28.014 | D35: 0 | E35: 0 | F35: Non-combustible
A37: CALCULATION METHODOLOGY
A38: Step 1: Get mol fraction (yi) for each component from composition data
A39: Step 2: Calculate heat contribution = yi × LHVi (BTU/scf per component)
A40: Step 3: Sum all contributions to get mixture LHV = Σ(yi × LHVi), then convert to other units
A42: STREAM: FLARE GAS (Old)
A43: Source: mol% from 'mol% to wt% Conversions' sheet (rows 32-45)
A44: Component | B44: mol% | C44: Mol Fraction | D44: LHV (BTU/scf) | E44: LHV Contrib
A45: Hydrogen | B45: ='mol% to wt% Conversions'!B32 -> 66.823331 | C45: =B45/100 -> 0.66823331 | D45: =$D$19 -> 275 | E45: =C45*D45 -> 183.76416
A46: Methane | B46: ='mol% to wt% Conversions'!B33 -> 18.035802 | C46: =B46/100 -> 0.18035802 | D46: =$D$20 -> 911 | E46: =C46*D46 -> 164.30616
A47: Ethane | B47: ='mol% to wt% Conversions'!B34 -> 3.9262561 | C47: =B47/100 -> 0.039262561 | D47: =$D$21 -> 1622 | E47: =C47*D47 -> 63.683874
A48: Ethylene | B48: ='mol% to wt% Conversions'!B35 -> 0.12777778 | C48: =B48/100 -> 0.0012777778 | D48: =$D$22 -> 1513 | E48: =C48*D48 -> 1.9332778
...

Sheet 1. ALL INPUT DATA
A1: MIDOR-ETHYDCO INTEGRATION - COMPLETE INPUT DATA
A2: Date: 2025-11-24 23:41:23
A4: 1. ECONOMIC PARAMETERS
A5: Parameter | B5: Value | C5: Source / Note
A6: NG Cost ($/MMBTU) | B6: 4.75 | C6: User provided - Egypt industrial NG price
A7: MJ to MMBTU Conversion | B7: 0.00094781699 | C7: 1 MMBTU = 1,055.056 MJ (standard)
A8: Operating Hours per Year | B8: 8000 | C8: Standard refinery operating hours
A10: 2. PRODUCT PRICES ($/ton)
A11: Product | B11: Price ($/ton) | C11: Source
A12: H2 (Hydrogen) | B12: 2000 | C12: Industry benchmark (not in Prices-25.xls)
A13: C2H6 (Ethane) | B13: 400 | C13: Industry benchmark (not in Prices-25.xls)
A14: C2H4 (Ethylene) | B14: 400 | C14: Industry benchmark (not in Prices-25.xls)
A15: LPG (C3+C4) | B15: 729 | C15: From Prices-25.xls (Jan 2025 average: $729/ton)
A16: C5+ (Light Naphtha) | B16: 620 | C16: From Prices-25.xls (Naphtha Jan avg: $620/ton)
A17: Methanol | B17: 450 | C17: Industry benchmark (not in Prices-25.xls)
A18: Ethylene (from MTO) | B18: 1200 | C18: Industry benchmark (not in Prices-25.xls)
A19: Propylene (from MTO) | B19: 900 | C19: Industry benchmark (not in Prices-25.xls)
A21: 3. MOLECULAR WEIGHTS (g/mol)
A22: Component | B22: MW (g/mol) | C22: Use
A23: H2 (Hydrogen) | B23: 2.016 | C23: For stoichiometry calculations
A24: CO (Carbon Monoxide) | B24: 28.01 | C24: For methanol synthesis
A25: CO2 (Carbon Dioxide) | B25: 44.01 | C25: For methanol synthesis
A26: CH3OH (Methanol) | B26: 32.04 | C26: For methanol synthesis
A28: 4. PROCESS PARAMETERS
A29: Parameter | B29: Value | C29: Source / Note
A30: Gasoline Density (g/cm³) | B30: 0.75 | C30: For methanol blending calculations
A31: Methanol Density (g/cm³) | B31: 0.79 | C31: For methanol blending calculations
A32: Methanol Blend Level (vol%) | B32: 5 | C32: Recommended blend level (5 vol%)
A33: MTO Ethylene Yield (%) | B33: 28 | C33: Typical MTO process yield
A34: MTO Propylene Yield (%) | B34: 42 | C34: Typical MTO process yield
A35: MIDOR Gasoline Pool (t/y) | B35: 1514271 | C35: From MIDOR production data
A36: ETHYDCO Feed Gap Min (T/hr) | B36: 11 | C36: From ETHYDCO.XLSX
A37: ETHYDCO Feed Gap Max (T/hr) | B37: 16 | C37: From ETHYDCO.XLSX
A38: ETHYDCO C2 Content (%) | B38: 95 | C38: C2 content in feed
A40: 5. STREAM DATA FROM MIDOR.XLSX
A41: Stream | B41: Flow (kg/h) | C41: LHV (MJ/kg) | D41: Flare % | E41: Fuel % | F41: Current Use | G41: Source
A42: Flare Gas (Old) | B42: 4122 | C42: ='Heat Content Calculations'!E70 -> 50.811859 | D42: 1 | E42: 0 | F42: Flared | G42: MIDOR.XLSX - calculations
A43: Flare Gas (New) | B43: 2989 | C43: ='Heat Content Calculations'!E101 -> 51.241227 | D43: 1 | E43: 0 | F43: Flared | G43: MIDOR.XLSX - calculations
A44: Off-Gas | B44: =13798541/30/24 -> 19164.64 | C44: ='Heat Content Calculations'!E134 -> 48.75527 | G44: MIDOR.XLSX - calculations
A45: Natural Gas | B45: =21092258/30/24 -> 29294.803 | C45: ='Heat Content Calculations'!E167 -> 45.999727 | G45: MIDOR.XLSX - calculations
...

Sheet 2. Stream Calculations
A1: STREAM-BY-STREAM CALCULATIONS
A2: Baseline Scenario: PSA/Sweep 100% fuel
A4: Parameter | B4: Flare Gas OLD | C4: Flare Gas New | D4: Refinery Gas | E4: PSA Purge | F4: Sweep Gas | G4: Penex | H4: TOTAL
A5: Flow (kg/h) | B5: ='1. ALL INPUT DATA'!B42 -> 4122 | C5: ='1. ALL INPUT DATA'!B43 -> 2989 | D5: ='1. ALL INPUT DATA'!B46 -> 48459.443 | E5: ='1. ALL INPUT DATA'!B47 -> 62786.449 | F5: ='1. ALL INPUT DATA'!B48 -> 3723.4181 | G5: ='1. ALL INPUT DATA'!B49 -> 2088.1164 | H5: =SUM(B5:G5) -> 124168.43
A6: Flow (t/y) | B6: =B5*'1. ALL INPUT DATA'!$B$8/1000 -> 32976 | C6: =C5*'1. ALL INPUT DATA'!$B$8/1000 -> 23912 | D6: =D5*'1. ALL INPUT DATA'!$B$8/1000 -> 387675.54 | E6: =E5*'1. ALL INPUT DATA'!$B$8/1000 -> 502291.59 | F6: =F5*'1. ALL INPUT DATA'!$B$8/1000 -> 29787.344 | G6: =G5*'1. ALL INPUT DATA'!$B$8/1000 -> 16704.931 | H6: =SUM(B6:G6) -> 993347.41
A7: LHV (MJ/kg) | B7: ='1. ALL INPUT DATA'!C42 -> 50.811859 | C7: ='1. ALL INPUT DATA'!C43 -> 51.241227 | D7: ='1. ALL INPUT DATA'!C46 -> 48.75527 | E7: ='1. ALL INPUT DATA'!C47 -> 7.8505607 | F7: ='1. ALL INPUT DATA'!C48 -> 53.299147 | G7: ='1. ALL INPUT DATA'!C49 -> 57.690623
A8: Fuel Fraction (for NG calc) | B8: ='1. ALL INPUT DATA'!E42 -> 0 | C8: ='1. ALL INPUT DATA'!E43 -> 0 | D8: ='1. ALL INPUT DATA'!E46 -> 1 | E8: ='1. ALL INPUT DATA'!E47 -> 1 | F8: ='1. ALL INPUT DATA'!E48 -> 1 | G8: ='1. ALL INPUT DATA'!E49 -> 1
A10: RECOVERABLE PRODUCTS (t/y)
A11: H2 | B11: =$B$6*'1. ALL INPUT DATA'!B53 -> 4031.7545 | C11: =$C$6*'1. ALL INPUT DATA'!C53 -> 3420.6586 | D11: =$D$6*'1. ALL INPUT DATA'!D53 -> 16074.739 | E11: =$E$6*'1. ALL INPUT DATA'!F53 -> 10645.689 | F11: =$F$6*'1. ALL INPUT DATA'!G53 -> 2766.3383 | G11: =$G$6*'1. ALL INPUT DATA'!H53 -> 2505.59 | H11: =SUM(B11:G11) -> 39444.769
A12: CH4 | B12: =$B$6*'1. ALL INPUT DATA'!B54 -> 8659.0331 | C12: =$C$6*'1. ALL INPUT DATA'!C54 -> 5530.7283 | D12: =$D$6*'1. ALL INPUT DATA'!D54 -> 194089.88 | E12: =$E$6*'1. ALL INPUT DATA'!F54 -> 39689.323 | F12: =$F$6*'1. ALL INPUT DATA'!G54 -> 2692.7876 | G12: =$G$6*'1. ALL INPUT DATA'!H54 -> 1076.0454 | H12: =SUM(B12:G12) -> 251737.8
A13: C2H6 | B13: =$B$6*'1. ALL INPUT DATA'!B55 -> 3533.2392 | C13: =$C$6*'1. ALL INPUT DATA'!C55 -> 1904.7015 | D13: =$D$6*'1. ALL INPUT DATA'!D55 -> 44081.53 | E13: =$E$6*'1. ALL INPUT DATA'!F55 -> 27.450051 | F13: =$F$6*'1. ALL INPUT DATA'!G55 -> 7396.0218 | G13: =$G$6*'1. ALL INPUT DATA'!H55 -> 2287.0817 | H13: =SUM(B13:G13) -> 59230.024
A14: C2H4 | B14: =$B$6*'1. ALL INPUT DATA'!B56 -> 107.27785 | C14: =$C$6*'1. ALL INPUT DATA'!C56 -> 87.30163 | D14: =$D$6*'1. ALL INPUT DATA'!D56 -> 1867.817 | E14: =$E$6*'1. ALL INPUT DATA'!F56 -> 0 | F14: =$F$6*'1. ALL INPUT DATA'!G56 -> 0 | G14: =$G$6*'1. ALL INPUT DATA'!H56 -> 0 | H14: =SUM(B14:G14) -> 2062.3965
A15: C3H8 | B15: =$B$6*'1. ALL INPUT DATA'!B57 -> 4103.6549 | C15: =$C$6*'1. ALL INPUT DATA'!C57 -> 2964.2442 | D15: =$D$6*'1. ALL INPUT DATA'!D57 -> 33870.467 | E15: =$E$6*'1. ALL INPUT DATA'!F57 -> 48.306393 | F15: =$F$6*'1. ALL INPUT DATA'!G57 -> 9011.3845 | G15: =$G$6*'1. ALL INPUT DATA'!H57 -> 7099.8963 | H15: =SUM(B15:G15) -> 57097.953
A16: C3H6 | B16: =$B$6*'1. ALL INPUT DATA'!B58 -> 286.26621 | C16: =$C$6*'1. ALL INPUT DATA'!C58 -> 242.37072 | D16: =$D$6*'1. ALL INPUT DATA'!D58 -> 2386.7284 | E16: =$E$6*'1. ALL INPUT DATA'!F58 -> 0 | F16: =$F$6*'1. ALL INPUT DATA'!G58 -> 0 | G16: =$G$6*'1. ALL INPUT DATA'!H58 -> 0 | H16: =SUM(B16:G16) -> 2915.3653
A17: iC4 | B17: =$B$6*'1. ALL INPUT DATA'!B59 -> 0 | C17: =$C$6*'1. ALL INPUT DATA'!C59 -> 0 | D17: =$D$6*'1. ALL INPUT DATA'!D59 -> 25906.319 | E17: =$E$6*'1. ALL INPUT DATA'!F59 -> 31.836363 | F17: =$F$6*'1. ALL INPUT DATA'!G59 -> 3903.4754 | G17: =$G$6*'1. ALL INPUT DATA'!H59 -> 3056.448 | H17: =SUM(B17:G17) -> 32898.078
A18: nC4 | B18: =$B$6*'1. ALL INPUT DATA'!B60 -> 3018.7111 | C18: =$C$6*'1. ALL INPUT DATA'!C60 -> 2630.7543 | D18: =$D$6*'1. ALL INPUT DATA'!D60 -> 34694.625 | E18: =$E$6*'1. ALL INPUT DATA'!F60 -> 24.761189 | F18: =$F$6*'1. ALL INPUT DATA'!G60 -> 2384.6688 | G18: =$G$6*'1. ALL INPUT DATA'!H60 -> 261.0944 | H18: =SUM(B18:G18) -> 43014.615
A19: C4= | B19: =$B$6*'1. ALL INPUT DATA'!B61 -> 2617.3884 | C19: =$C$6*'1. ALL INPUT DATA'!C61 -> 2014.3987 | D19: =$D$6*'1. ALL INPUT DATA'!D61 -> 0 | E19: =$E$6*'1. ALL INPUT DATA'!F61 -> 0 | F19: =$F$6*'1. ALL INPUT DATA'!G61 -> 0 | G19: =$G$6*'1. ALL INPUT DATA'!H61 -> 0 | H19: =SUM(B19:G19) -> 4631.7871
A20: I-C5 | B20: =$B$6*'1. ALL INPUT DATA'!B62 -> 0 | C20: =$C$6*'1. ALL INPUT DATA'!C62 -> 0 | D20: =$D$6*'1. ALL INPUT DATA'!D62 -> 0 | E20: =$E$6*'1. ALL INPUT DATA'!F62 -> 0 | F20: =$F$6*'1. ALL INPUT DATA'!G62 -> 0 | G20: =$G$6*'1. ALL INPUT DATA'!H62 -> 0 | H20: =SUM(B20:G20) -> 0
A21: N-C5 | B21: =$B$6*'1. ALL INPUT DATA'!B63 -> 1255.2067 | C21: =$C$6*'1. ALL INPUT DATA'!C63 -> 822.18662 | D21: =$D$6*'1. ALL INPUT DATA'!D63 -> 0 | E21: =$E$6*'1. ALL INPUT DATA'!F63 -> 0 | F21: =$F$6*'1. ALL INPUT DATA'!G63 -> 0 | G21: =$G$6*'1. ALL INPUT DATA'!H63 -> 399.61481 | H21: =SUM(B21:G21) -> 2477.0081
A22: N-C6 | B22: =$B$6*'1. ALL INPUT DATA'!B64 -> 1285.1091 | C22: =$C$6*'1. ALL INPUT DATA'!C64 -> 926.71223 | D22: =$D$6*'1. ALL INPUT DATA'!D64 -> 0 | E22: =$E$6*'1. ALL INPUT DATA'!F64 -> 0 | F22: =$F$6*'1. ALL INPUT DATA'!G64 -> 0 | G22: =$G$6*'1. ALL INPUT DATA'!H64 -> 0 | H22: =SUM(B22:G22) -> 2211.8214
... A27: N2 | B27: =$B$6*'1. ALL INPUT DATA'!B69 -> 1834.0078 | C27: =$C$6*'1. ALL INPUT DATA'!C69 -> 1624.6824 | D27: =$D$6*'1. ALL INPUT DATA'!D69 -> 0 | E27: =$E$6*'1. ALL INPUT DATA'!F69 -> 0 | F27: =$F$6*'1. ALL INPUT DATA'!G69 -> 0 | G27: =$G$6*'1. ALL INPUT DATA'!H69 -> 0 | H27: =SUM(B27:G27) -> 3458.6902
A29: AGGREGATE PRODUCTS (t/yr)
A30: Total C2 (C2H6 + C2H4) | B30: =B13+B14 -> 3640.517 | C30: =C13+C14 -> 1992.0031 | D30: =D13+D14 -> 45949.347 | E30: =E13+E14 -> 27.450051 | F30: =F13+F14 -> 7396.0218 | G30: =G13+G14 -> 2287.0817 | H30: =SUM(B30:F30) -> 59005.339
A31: Total C3 LPG (C3H8 + C3H6) | B31: =B15+B16 -> 4389.9211 | C31: =C15+C16 -> 3206.6149 | D31: =D15+D16 -> 36257.195 | E31: =E15+E16 -> 48.306393 | F31: =F15+F16 -> 9011.3845 | G31: =G15+G16 -> 7099.8963 | H31: =SUM(B31:F31) -> 52913.422
A32: Total C4 LPG (iC4 + nC4) | B32: =B17+B18 -> 3018.7111 | C32: =C17+C18 -> 2630.7543 | D32: =D17+D18 -> 60600.943 | E32: =E17+E18 -> 56.597552 | F32: =F17+F18 -> 6288.1442 | G32: =G17+G18 -> 3317.5424 | H32: =SUM(B32:F32) -> 72595.151
A33: Total LPG (C3 + C4) | B33: =B31+B32 -> 7408.6323 | C33: =C31+C32 -> 5837.3692 | D33: =D31+D32 -> 96858.139 | E33: =E31+E32 -> 104.90395 | F33: =F31+F32 -> 15299.529 | G33: =G31+G32 -> 10417.439 | H33: =SUM(B33:F33) -> 125508.57
A34: C5+ | B34: =B20+B21+B22+B23 -> 2540.3158 | C34: =C20+C21+C22+C23 -> 1748.8988 | D34: =D20+D21+D22+D23 -> 15659.191 | E34: =E20+E21+E22+E23 -> 152.02789 | F34: =F20+F21+F22+F23 -> 1632.668 | G34: =G20+G21+G22+G23 -> 418.77499 | H34: =SUM(B34:F34) -> 21733.102
A36: NG MAKEUP ECONOMICS
A37: Heat Content (MJ/h) | B37: =B5*B7 -> 209446.48 | C37: =C5*C7 -> 153160.03 | D37: =D5*D7 -> 2362653.2 | E37: =E5*E7 -> 492908.83 | F37: =F5*F7 -> 198455.01 | G37: =G5*G7 -> 120464.73
A38: Heat Content (MMBTU/h) | B38: =B37*'1. ALL INPUT DATA'!$B$7 -> 198.51693 | C38: =C37*'1. ALL INPUT DATA'!$B$7 -> 145.16768 | D38: =D37*'1. ALL INPUT DATA'!$B$7 -> 2239.3629 | E38: =E37*'1. ALL INPUT DATA'!$B$7 -> 467.18736 | F38: =F37*'1. ALL INPUT DATA'!$B$7 -> 188.09903 | G38: =G37*'1. ALL INPUT DATA'!$B$7 -> 114.17852
A39: Heat from Fuel Portion (MMBTU/h) | B39: =B38*B8 -> 0 | C39: =C38*C8 -> 0 | D39: =D38*D8 -> 2239.3629 | E39: =E38*E8 -> 467.18736 | F39: =F38*F8 -> 188.09903 | G39: =G38*G8 -> 114.17852
A40: NG Needed (MMBTU/y) | B40: =B39*'1. ALL INPUT DATA'!$B$8 -> 0 | C40: =C39*'1. ALL INPUT DATA'!$B$8 -> 0 | D40: =D39*'1. ALL INPUT DATA'!$B$8 -> 17914903 | E40: =E39*'1. ALL INPUT DATA'!$B$8 -> 3737498.9 | F40: =F39*'1. ALL INPUT DATA'!$B$8 -> 1504792.2 | G40: =G39*'1. ALL INPUT DATA'!$B$8 -> 913428.17 | H40: =SUM(B40:G40) -> 24070622
A41: NG Cost ($/y) | B41: =B40*'1. ALL INPUT DATA'!$B$6 -> 0 | C41: =C40*'1. ALL INPUT DATA'!$B$6 -> 0 | D41: =D40*'1. ALL INPUT DATA'!$B$6 -> 85095789 | E41: =E40*'1. ALL INPUT DATA'!$B$6 -> 17753120 | F41: =F40*'1. ALL INPUT DATA'!$B$6 -> 7147763.1 | G41: =G40*'1. ALL INPUT DATA'!$B$6 -> 4338783.8 | H41: =SUM(B41:G41) -> 1.1433546e+08
A43: PRODUCT VALUES ($/y)
A44: H2 Value | B44: =B11*'1. ALL INPUT DATA'!$B$12 -> 8063508.9 | C44: =C11*'1. ALL INPUT DATA'!$B$12 -> 6841317.1 | D44: =D11*'1. ALL INPUT DATA'!$B$12 -> 32149477 | E44: =E11*'1. ALL INPUT DATA'!$B$12 -> 21291377 | F44: =F11*'1. ALL INPUT DATA'!$B$12 -> 5532676.6 | G44: =G11*'1. ALL INPUT DATA'!$B$12 -> 5011180 | H44: =SUM(B44:G44) -> 78889537
A45: C2 Value | B45: =B30*'1. ALL INPUT DATA'!$B$13 -> 1456206.8 | C45: =C30*'1. ALL INPUT DATA'!$B$13 -> 796801.24 | D45: =D30*'1. ALL INPUT DATA'!$B$13 -> 18379739 | E45: =E30*'1. ALL INPUT DATA'!$B$13 -> 10980.02 | F45: =F30*'1. ALL INPUT DATA'!$B$13 -> 2958408.7 | G45: =G30*'1. ALL INPUT DATA'!$B$13 -> 914832.69 | H45: =SUM(B45:G45) -> 24516968
A46: LPG Value | B46: =B33*'1. ALL INPUT DATA'!$B$15 -> 5400892.9 | C46: =C33*'1. ALL INPUT DATA'!$B$15 -> 4255442.1 | D46: =D33*'1. ALL INPUT DATA'!$B$15 -> 70609583 | E46: =E33*'1. ALL INPUT DATA'!$B$15 -> 76474.976 | F46: =F33*'1. ALL INPUT DATA'!$B$15 -> 11153356 | G46: =G33*'1. ALL INPUT DATA'!$B$15 -> 7594312.8 | H46: =SUM(B46:G46) -> 99090063
A47: C5+ Value | B47: =B23*'1. ALL INPUT DATA'!$B$16 -> 0 | C47: =C23*'1. ALL INPUT DATA'!$B$16 -> 0 | D47: =D23*'1. ALL INPUT DATA'!$B$16 -> 9708698.5 | E47: =E23*'1. ALL INPUT DATA'!$B$16 -> 94257.293 | F47: =F23*'1. ALL INPUT DATA'!$B$16 -> 1012254.2 | G47: =G23*'1. ALL INPUT DATA'!$B$16 -> 11879.317 | H47: =SUM(B47:G47) -> 10827089
A48: TOTAL PRODUCT VALUE | B48: =SUM(B44:B47) -> 14920609 | C48: =SUM(C44:C47) -> 11893560 | D48: =SUM(D44:D47) -> 1.308475e+08 | E48: =SUM(E44:E47) -> 21473089 | F48: =SUM(F44:F47) -> 20656696 | G48: =SUM(G44:G47) -> 13532205 | H48: =SUM(H44:H47) -> 2.1332366e+08
A50: NET ECONOMICS
...

Sheet 3. Calc 1 - LPG & C5+
A1: CALCULATION 1: C3, C4, C5+ RECOVERY
A3: Parameter | B3: Quantity (t/y) | C3: Formula / Source
A4: Total C3 (Propane+Propylene) | B4: ='2. Stream Calculations'!H31 -> 52913.422
A5: Total C4 (Butanes) | B5: ='2. Stream Calculations'!H32 -> 72595.151
A6: TOTAL LPG (C3+C4) | B6: =B4+B5 -> 125508.57
A7: Total C5+ | B7: ='2. Stream Calculations'!H34 -> 21733.102
A9: LPG Value | B9: =B6*'1. ALL INPUT DATA'!B15 -> 91495750
A10: C5+ Value | B10: =B7*'1. ALL INPUT DATA'!B16 -> 13474523
A11: Total Product Value | B11: =B9+B10 -> 1.0497027e+08
A13: LPG heat content ( average ) | B13: ='Heat Content Calculations'!H328 -> 43.409593 | C13: MMBTU /ton
A14: LPG heat content per year | B14: =('2. Stream Calculations'!D33+'2. Stream Calculations'!E33+'2. Stream Calculations'!F33+'2. Stream Calculations'!G33)*B13 -> 5325489.3 | C14: MMBTU/year
A15: C5+ Heat content (average ) | B15: ='Heat Content Calculations'!H396 -> 40.577162 | C15: MMBTU /ton
A16: C5+ Heat content per year | B16: =('2. Stream Calculations'!D34+'2. Stream Calculations'!E34+'2. Stream Calculations'!F34+'2. Stream Calculations'!G34)*B15 -> 724816.14 | C16: MMBTU/year
A18: Total product heat content per year | B18: =B16+B14 -> 6050305.5 | C18: MMBTU/ year
A20: NG Make-up Cost | B20: =B18*'1. ALL INPUT DATA'!B6 -> 28738951
A22: NET VALUE (Calc 1) $/year | B22: =B11-B20 -> 76231322

Sheet 4. Calc 2 - H2 Recovery
A1: CALCULATION 2: H2 RECOVERY FROM ALL STREAMS
A3: Parameter | B3: Quantity (t/y) | C3: Formula / Source
A4: H2 from Off-Gas | B4: ='2. Stream Calculations'!D11 -> 16074.739
A5: H2 from Flare Gas OLD | B5: ='2. Stream Calculations'!B11 -> 4031.7545
A6: H2 from Flare Gas New | B6: ='2. Stream Calculations'!C11 -> 3420.6586
A7: H2 from PSA Purge | B7: ='2. Stream Calculations'!E11 -> 10645.689
A8: H2 from Sweep Gas | B8: ='2. Stream Calculations'!F11 -> 2766.3383
A9: H2 from Penex | B9: ='2. Stream Calculations'!G11 -> 2505.59
A11: TOTAL H2 RECOVERY | B11: =SUM(B4:B9) -> 39444.769 | C11: t/y
A12: Total H2 Value | B12: =B11*'1. ALL INPUT DATA'!B12 -> 78889537
A14: H2 heat content | B14: ='Heat Content Calculations'!H362 -> 114.02448 | C14: MMBTU /ton
A16: Total H2 heat content per year | B16: =('2. Stream Calculations'!D11+'2. Stream Calculations'!E11+'2. Stream Calculations'!F11+'2. Stream Calculations'!G11)*B14 -> 3647911.6 | C16: MMBTU /year
A18: NG Make-up Cost | B18: =B16*'1. ALL INPUT DATA'!B6 -> 17327580
A20: NET VALUE (Calc 2) $/year | B20: =B12-B18 -> 61561957

Sheet 5. Calc 3 - C2 Balance
A1: CALCULATION 3: C2 BALANCE & ETHYDCO SUPPLY-DEMAND
A3: Parameter | B3: Quantity | C3: Formula / Source
A4: MIDOR C2 Supply (t/y) | B4: ='2. Stream Calculations'!H30 -> 59005.339
A6: ETHYDCO Feed Gap Min (T/hr) | B6: ='1. ALL INPUT DATA'!B36 -> 11
A7: ETHYDCO Feed Gap Max (T/hr) | B7: ='1. ALL INPUT DATA'!B37 -> 16
A8: C2 Content (%) | B8: ='1. ALL INPUT DATA'!B38/100 -> 0.95
A10: ETHYDCO C2 Need Min (t/y) | B10: ='1. ALL INPUT DATA'!B36*'1. ALL INPUT DATA'!B8*B8 -> 83600
A11: ETHYDCO C2 Need Max (t/y) | B11: ='1. ALL INPUT DATA'!B37*'1. ALL INPUT DATA'!B8*B8 -> 121600
A13: Balance vs Min (t/y) | B13: =B4-B10 -> -24594.661
A14: Coverage of Min (%) | B14: =B4/B10 -> 0.70580549
A15: Coverage of Max (%) | B15: =B4/B11 -> 0.48524127
A17: Total C2 Value ($/y) | B17: =B4*'1. ALL INPUT DATA'!B13 -> 23602136

Sheet 6. Calc 4 - CO & CO2
A1: CALCULATION 4: CO & CO2 FOR METHANOL
A3: Parameter | B3: Quantity (t/y) | C3: Formula / Source
A4: Total CO Available | B4: ='2. Stream Calculations'!H25 -> 65956.116
A5: Total CO2 Available | B5: ='2. Stream Calculations'!H26 -> 408747.17
A7: CO:CO2 Ratio | B7: =B4/B5 -> 0.16136165

Sheet 7. Calc 5 - Methanol
A1: CALCULATION 5: METHANOL PRODUCTION
A3: Parameter | B3: Value | C3: Formula / Source
A4: H2 for CO (t/y) conversion to methanol | B4: ='6. Calc 4 - CO & CO2'!B4*2*'1. ALL INPUT DATA'!B23/'1. ALL INPUT DATA'!B24 -> 9494.2899 | C4: CO × 2 × MW(H2)/MW(CO)
A5: H2 for CO2 (t/y) conversion to methanol | B5: ='6. Calc 4 - CO & CO2'!B5*3*'1. ALL INPUT DATA'!B23/'1. ALL INPUT DATA'!B25 -> 56171.39 | C5: CO2 × 3 × MW(H2)/MW(CO2)
A6: TOTAL H2 REQUIRED (t/y) | B6: =B4+B5 -> 65665.68
A8: SCENARIO 2: With H2 Augmentation (Recommended)
A9: H2 Available (t/y) | B9: ='4. Calc 2 - H2 Recovery'!B11 -> 39444.769
A10: H2 Deficit (t/y) | B10: =B6-B9 -> 26220.911
A11: H2 Utilization Fraction | B11: =B9/B6 -> 0.60069078
A13: Methanol from CO (t/y) with available H2 | B13: ='6. Calc 4 - CO & CO2'!B4*B11*'1. ALL INPUT DATA'!B26/'1. ALL INPUT DATA'!B24 -> 45319.534 | C13: Total CO × Utilization Fraction × (MW of MeOH / MW of CO)
A14: Methanol from CO2 (t/y) with available H2 | B14: ='6. Calc 4 - CO & CO2'!B5*'7. Calc 5 - Methanol'!B11*'1. ALL INPUT DATA'!B26/'1. ALL INPUT DATA'!B25 -> 178750.33 | C14: Total CO₂ × Utilization Fraction × (MW of MeOH / MW of CO₂)
A15: TOTAL METHANOL S2 (t/y) ✓ RECOMMENDED | B15: =B13+B14 -> 224069.87

Sheet 9. Final Summary
A1: FINAL INTEGRATION VALUE SUMMARY
A3: Phase | B3: NET VALUE ($/year) | C3: Description
A4: Phase 1+2: Off-Gas & Flare Recovery
A5: LPG & C5+ NET | B5: ='3. Calc 1 - LPG & C5+'!B22 -> 76231322 | C5: From Calc 1
A6: C2 Value | B6: ='5. Calc 3 - C2 Balance'!B17 -> 23602136 | C6: From Calc 3
A7: Phase 1+2 Gross Value | B7: =B5+B6+'3. Calc 1 - LPG & C5+'!B22 -> 1.7606478e+08
A8: Phase 1+2 NG Cost | B8: ='3. Calc 1 - LPG & C5+'!B22 -> 76231322
A9: Phase 1+2 NET VALUE | B9: =B7-B8 -> 99833457 | C9: Gross - NG cost
A11: Phase 3+4: Methanol & MTO
A12: Phase 3+4 NET VALUE | B12: ='8. Calc 6 - Blend & MTO'!B21 -> 96232485 | C12: From Calc 6
A14: TOTAL INTEGRATION VALUE
A15: Total NG Makeup Cost ($/year) | B15: =B8+'8. Calc 6 - Blend & MTO'!B20 -> 76231322
A16: TOTAL NET VALUE ($/year) | B16: =B9+B12 -> 1.9606594e+08 | C16: After all NG makeup costs

Sheet 8. Calc 6 - Blend & MTO
A1: CALCULATION 6: METHANOL BLENDING & MTO
A3: Parameter | B3: Value | C3: Formula / Source
A4: Gasoline Pool (t/y) | B4: ='1. ALL INPUT DATA'!B35 -> 1514271
A5: Methanol Available S2 (t/y) | B5: ='7. Calc 5 - Methanol'!B15 -> 224069.87
A7: Blend vol% | B7: ='1. ALL INPUT DATA'!B32/100 -> 0.05
A8: Blend wt% | B8: =(B7*'1. ALL INPUT DATA'!B31)/((B7*'1. ALL INPUT DATA'!B31)+((1-B7)*'1. ALL INPUT DATA'!B30)) -> 0.052526596 | C8: (Blend vol% × ρ_methanol) / [(Blend vol% × ρ_methanol) + ((1 - Blend vol%) × ρ_gasoline)]
A9: Methanol in Gasoline (t/y) | B9: =B4*B8 -> 79539.501
A10: Methanol Surplus for MTO (t/y) | B10: =B5-B9 -> 144530.37
A12: Ethylene from MTO (t/y) | B12: =B10*'1. ALL INPUT DATA'!B33/100 -> 40468.503
A13: Propylene from MTO (t/y) | B13: =B10*'1. ALL INPUT DATA'!B34/100 -> 60702.754
A15: Methanol in Gasoline Value ($/y) | B15: =B9*'1. ALL INPUT DATA'!B17 -> 35792775
A16: Ethylene Value ($/y) | B16: =B12*'1. ALL INPUT DATA'!B14 -> 16187401
A17: Propylene Value ($/y) | B17: =B13*'1. ALL INPUT DATA'!B15 -> 44252308
A18: Phase 3+4 Total Value ($/y) | B18: =B15+B16+B17 -> 96232485
A20: Phase 3 NG Cost (PSA+Sweep) ($/y) | B20: ='2. Stream Calculations'!E42+'2. Stream Calculations'!F42 -> 0
A21: Phase 3+4 NET VALUE ($/y) | B21: =B18-B20 -> 96232485
